<?xml version="1.0" encoding="utf-8"?>
<!-- This URDF was automatically created by SolidWorks to URDF Exporter! Originally created by Stephen Brawner (brawner@gmail.com)
     Commit Version: 1.6.0-1-g15f4949  Build Version: 1.6.7594.29634
     For more information, please see http://wiki.ros.org/sw_urdf_exporter -->
<robot name="robot">
  <link name="body">
    <inertial>
      <origin xyz="0 0 0" rpy="0 0 0" />
      <mass value="5.759748808" />
      <inertia ixx="0.018914220659674" ixy="0" ixz="0"
        iyy="0.044772130588725" iyz="0" izz="0.052670277508692" />
    </inertial>
    <visual>
      <origin xyz="0 0 0" rpy="0 0 0" />
      <geometry>
        <mesh filename="meshes/body.STL"/>
      </geometry>
    </visual>
    <collision>
      <origin xyz="0 0 0" rpy="0 0 0" />
      <geometry>
        <mesh filename="meshes/body.STL"/>
      </geometry>
    </collision>
  </link>


  <!--!!!!!!!!!!!! Front Right Leg !!!!!!!!!!!!!!!!!!!!!!!!!!!!!!!!!!!!-->
  <link name="rf1">
    <inertial>
      <origin xyz="0.050813966714 0.000060533110 -0.003485784008" rpy="0 0 0" />
      <mass value="0.679697812" />
      <inertia ixx="0.000443058661539" ixy="-0.000001109650184" ixz="0.000006157383350"
        iyy="0.000498026538445" iyz="0.000000852511417" izz="0.000726566430948" />
    </inertial>
    <visual>
      <origin xyz="0 0 0" rpy="0 0 0" />
      <geometry>
        <mesh filename="meshes/rf1.STL" />
      </geometry>
    </visual>
    <collision>
      <origin xyz="0 0 0" rpy="0 0 0" />
      <geometry>
        <mesh filename="meshes/rf1.STL" />
      </geometry>
    </collision>
  </link>

  <joint name="rfjoint1" type="continuous">
    <origin xyz="0.1326 -0.049 0" rpy="-1.5708 0 0" />
    <parent link="body" />
    <child link="rf1" />
    <axis xyz="1 0 0" />
  </joint>

  <link name="rf2">
    <inertial>
      <origin xyz="0.041357821694 -0.001434049578 0.025938637371" rpy="0 0 0" />
      <mass value="0.953007111" />
      <inertia ixx="0.004510673821221" ixy="0.000044039609609" ixz="-0.000684645283926"
        iyy="0.004496442293817" iyz="0.000124878546196" izz="0.000782040598148" />
    </inertial>
    <visual>
      <origin xyz="0 0 0" rpy="0 0 0" />
      <geometry>
        <mesh filename="meshes/rf2.STL" />
      </geometry>
    </visual>
    <collision>
      <origin xyz="0 0 0" rpy="0 0 0" />
      <geometry>
        <mesh filename="meshes/rf2.STL" />
      </geometry>
    </collision>
  </link>

  <joint name="rfjoint2" type="continuous">
    <origin xyz="0.053 0 -0.0273" rpy="-1.5708 1.5708 0" />
    <parent link="rf1" />
    <child link="rf2" />
    <axis xyz="1 0 0" />
  </joint>

  <link name="rf3">
    <inertial>
      <origin xyz="0.013500041538 -0.000357486919 0.105642978108" rpy="0 0 0" />
      <mass value="0.101126826" />
      <inertia ixx="0.000624594596470" ixy="0.000000000006712" ixz="-0.000000000238118"
        iyy="0.000622367653807" iyz="-0.000004386948249" izz="0.000009078971542" />
    </inertial>
    <visual>
      <origin xyz="0 0 0" rpy="0 0 0" />
      <geometry>
        <mesh filename="meshes/rf3.STL" />
      </geometry>
    </visual>
    <collision>
      <origin xyz="0 0 0" rpy="0 0 0" />
      <geometry>
        <mesh filename="meshes/rf3.STL" />
      </geometry>
    </collision>
  </link>

  <joint name="rfjoint3" type="continuous">
    <origin xyz="0.05485 0 0.21" rpy="0 0 0" />
    <parent link="rf2" />
    <child link="rf3" />
    <axis xyz="1 0 0" />
  </joint>

  <link name="rf4">
    <contact>
      <friction_anchor/>
      <stiffness value="30000.0"/>
      <damping value="1000.0"/>
      <spinning_friction value="0.3"/>
      <lateral_friction value="1.2"/>
    </contact>
    <visual>
      <origin rpy="0 0 0" xyz="0 0 0"/>
      <geometry>
        <sphere radius="0.016"/>
      </geometry>
      <material name="darkgray"/>
    </visual>
    <collision>
      <origin rpy="0 0 0" xyz="0 0 0"/>
      <geometry>
        <sphere radius="0.016"/>
      </geometry>
    </collision>
    <inertial>
      <mass value="0"/>
      <inertia ixx="0" ixy="0" ixz="0" iyy="0" iyz="0" izz="0"/>
    </inertial>
  </link>

  <joint name="rfjoint4" type="fixed">
    <parent link="rf3"/>
    <child link="rf4"/>
    <origin xyz="0.0135 0 0.205"/>
    <dynamics damping="0.0" friction="0.0"/>
  </joint>


  <!--!!!!!!!!!!!! Front Left Leg !!!!!!!!!!!!!!!!!!!!!!!!!!!!!!!!!!!!-->
  <link name="lf1">
    <inertial>
      <origin xyz="0.050813966714 0.000060533110 -0.003485784008" rpy="0 0 0" />
      <mass value="0.679697812" />
      <inertia ixx="0.000443058661539" ixy="-0.000001109650184" ixz="0.000006157383350"
        iyy="0.000498026538445" iyz="0.000000852511417" izz="0.000726566430948" />
    </inertial>
    <visual>
      <origin xyz="0 0 0" rpy="0 0 0" />
      <geometry>
        <mesh filename="meshes/lf1.STL" />
      </geometry>
    </visual>
    <collision>
      <origin xyz="0 0 0" rpy="0 0 0" />
      <geometry>
        <mesh filename="meshes/lf1.STL" />
      </geometry>
    </collision>
  </link>

  <joint name="lfjoint1" type="continuous">
    <origin xyz="0.1326 0.049 0" rpy="1.5708 0 0" />
    <parent link="body" />
    <child link="lf1" />
    <axis xyz="1 0 0" />
  </joint>



  <link name="lf2">
    <inertial>
      <origin xyz="0.041357821694 -0.001434049578 -0.025938637371" rpy="0 0 0" />
      <mass value="0.953007111" />
      <inertia ixx="0.004510673821221" ixy="0.000044039609609" ixz="0.000684645283926"
        iyy="0.004496442293817" iyz="-0.000124878546196" izz="0.000782040598148" />
    </inertial>
    <visual>
      <origin xyz="0 0 0" rpy="0 0 0" />
      <geometry>
        <mesh filename="meshes/lf2.STL" />
      </geometry>
    </visual>
    <collision>
      <origin xyz="0 0 0" rpy="0 0 0" />
      <geometry>
        <mesh filename="meshes/lf2.STL" />
      </geometry>
    </collision>
  </link>

  <joint name="lfjoint2" type="continuous">
    <origin xyz="0.053 0 -0.0273" rpy="-1.5708 1.5708 0" />
    <parent link="lf1" />
    <child link="lf2" />
    <axis xyz="-1 0 0" />
  </joint>

  <link name="lf3">
    <inertial>
      <origin xyz="-0.013500041538 -0.000357486919 0.105642978108" rpy="0 0 0" />
      <mass value="0.101126826" />
      <inertia ixx="0.000624594596470" ixy="0.000000000006712" ixz="-0.000000000238118"
        iyy="0.000622367653807" iyz="-0.000004386948249" izz="0.000009078971542" />
    </inertial>
    <visual>
      <origin xyz="0 0 0" rpy="0 0 0" />
      <geometry>
        <mesh filename="meshes/lf3.STL" />
      </geometry>
    </visual>
    <collision>
      <origin
        xyz="0 0 0"
        rpy="0 0 0" />
      <geometry>
        <mesh
          filename="meshes/lf3.STL" />
      </geometry>
    </collision>
  </link>

  <joint name="lfjoint3" type="continuous">
    <origin xyz="0.05485 0 -0.21" rpy="3.1416 0 -3.1416" />
    <parent link="lf2" />
    <child link="lf3" />
    <axis xyz="1 0 0" />
  </joint>

  <link name="lf4">
    <contact>
      <friction_anchor/>
      <stiffness value="30000.0"/>
      <damping value="1000.0"/>
      <spinning_friction value="0.3"/>
      <lateral_friction value="1.2"/>
    </contact>
    <visual>
      <origin rpy="0 0 0" xyz="0 0 0"/>
      <geometry>
        <sphere radius="0.016"/>
      </geometry>
      <material name="darkgray"/>
    </visual>
    <collision>
      <origin rpy="0 0 0" xyz="0 0 0"/>
      <geometry>
        <sphere radius="0.016"/>
      </geometry>
    </collision>
    <inertial>
      <mass value="0"/>
      <inertia ixx="0" ixy="0" ixz="0" iyy="0" iyz="0" izz="0"/>
    </inertial>
  </link>

  <joint name="lfjoint4" type="fixed">
    <parent link="lf3"/>
    <child link="lf4"/>
    <origin xyz="-0.0135 0 0.205"/>
    <dynamics damping="0.0" friction="0.0"/>
  </joint>




  <!--!!!!!!!!!!!! Back Right Leg !!!!!!!!!!!!!!!!!!!!!!!!!!!!!!!!!!!!-->
  <link name="rb1">
    <inertial>
      <origin xyz="0.050813966714 0.000060533110 -0.003485784008" rpy="0 0 0" />
      <mass value="0.679697812" />
      <inertia ixx="0.000443058661539" ixy="-0.000001109650184" ixz="0.000006157383350"
        iyy="0.000498026538445" iyz="0.000000852511417" izz="0.000726566430948" />
    </inertial>
    <visual>
      <origin xyz="0 0 0" rpy="0 0 0" />
      <geometry>
        <mesh filename="meshes/rb1.STL" />
      </geometry>
    </visual>
    <collision>
      <origin xyz="0 0 0" rpy="0 0 0" />
      <geometry>
        <mesh filename="meshes/rb1.STL" />
      </geometry>
    </collision>
  </link>

  <joint name="rbjoint1" type="continuous">
    <origin xyz="-0.1326 -0.049 0" rpy="1.5707963267949 0 3.14159265358979" />
    <parent link="body" />
    <child link="rb1" />
    <axis xyz="-1 0 0" />
  </joint>

  <link name="rb2">
    <inertial>
      <origin xyz="0.041357821694 0.001434049578 0.025938637371" rpy="0 0 0" />
      <mass value="0.953007111" />
      <inertia ixx="0.004510673821221" ixy="-0.000044039609609" ixz="-0.000684645283926"
        iyy="0.004496442293817" iyz="-0.000124878546196" izz="0.000782040598148" />
    </inertial>
    <visual>
      <origin xyz="0 0 0" rpy="0 0 0" />
      <geometry>
        <mesh filename="meshes/rb2.STL" />
      </geometry>
    </visual>
    <collision>
      <origin xyz="0 0 0" rpy="0 0 0" />
      <geometry>
        <mesh filename="meshes/rb2.STL" />
      </geometry>
    </collision>
  </link>

  <joint name="rbjoint2" type="continuous">
    <origin xyz="0.053 0 -0.0273" rpy="1.5707963267949 1.5707963267949 0" />
    <parent link="rb1" />
    <child link="rb2" />
    <axis xyz="1 0 0" />
  </joint>

  <link name="rb3">
    <inertial>
      <origin xyz="-0.013500041538 0.000357486919 -0.105642978108" rpy="0 0 0" />
      <mass value="0.101126826" />
      <inertia ixx="0.000624594596470" ixy="-0.000000000006712" ixz="0.000000000238118"
        iyy="0.000622367653807" iyz="-0.000004386948249" izz="0.000009078971542" />
    </inertial>
    <visual>
      <origin xyz="0 0 0" rpy="0 0 0" />
      <geometry>
        <mesh filename="meshes/rb3.STL" />
      </geometry>
    </visual>
    <collision>
      <origin xyz="0 0 0" rpy="0 0 0" />
      <geometry>
        <mesh filename="meshes/rb3.STL" />
      </geometry>
    </collision>
  </link>

  <joint name="rbjoint3" type="continuous">
    <origin xyz="0.05485 0 0.21" rpy="3.1416 0 3.1416" />
    <parent link="rb2" />
    <child link="rb3" />
    <axis xyz="-1 0 0" />
  </joint>

  <link name="rb4">
    <contact>
      <friction_anchor/>
      <stiffness value="30000.0"/>
      <damping value="1000.0"/>
      <spinning_friction value="0.3"/>
      <lateral_friction value="1.2"/>
    </contact>
    <visual>
      <origin rpy="0 0 0" xyz="0 0 0"/>
      <geometry>
        <sphere radius="0.016"/>
      </geometry>
      <material name="darkgray"/>
    </visual>
    <collision>
      <origin rpy="0 0 0" xyz="0 0 0"/>
      <geometry>
        <sphere radius="0.016"/>
      </geometry>
    </collision>
    <inertial>
      <mass value="0"/>
      <inertia ixx="0" ixy="0" ixz="0" iyy="0" iyz="0" izz="0"/>
    </inertial>
  </link>

  <joint name="rbjoint4" type="fixed">
    <parent link="rb3"/>
    <child link="rb4"/>
    <origin xyz="-0.0135 0 -0.205"/>
    <dynamics damping="0.0" friction="0.0"/>
  </joint>


  <!--!!!!!!!!!!!! Back Left Leg !!!!!!!!!!!!!!!!!!!!!!!!!!!!!!!!!!!!-->
  <link name="lb1">
    <inertial>
      <origin xyz="0.050813966714 0.000060533110 -0.003485784008" rpy="0 0 0" />
      <mass value="0.679697812" />
      <inertia ixx="0.000443058661539" ixy="-0.000001109650184" ixz="0.000006157383350"
        iyy="0.000498026538445" iyz="0.000000852511417" izz="0.000726566430948" />
    </inertial>
    <visual>
      <origin xyz="0 0 0" rpy="0 0 0" />
      <geometry>
        <mesh filename="meshes/lb1.STL" />
      </geometry>
    </visual>
    <collision>
      <origin xyz="0 0 0" rpy="0 0 0" />
      <geometry>
        <mesh filename="meshes/lb1.STL" />
      </geometry>
    </collision>
  </link>

  <joint name="lbjoint1" type="continuous">
    <origin xyz="-0.1326 0.049 0" rpy="-1.5708 0 3.1416" />
    <parent link="body" />
    <child link="lb1" />
    <axis xyz="-1 0 0" />
  </joint>

  <link name="lb2">
    <inertial>
      <origin xyz="0.041357821694 -0.001434049578 0.025938637371" rpy="0 0 0" />
      <mass value="0.953007111" />
      <inertia ixx="0.004510673821221" ixy="0.000044039609609" ixz="-0.000684645283926"
        iyy="0.004496442293817" iyz="0.000124878546196" izz="0.000782040598148" />
    </inertial>
    <visual>
      <origin xyz="0 0 0" rpy="0 0 0" />
      <geometry>
        <mesh filename="meshes/lb2.STL" />
      </geometry>
    </visual>
    <collision>
      <origin xyz="0 0 0" rpy="0 0 0" />
      <geometry>
        <mesh filename="meshes/lb2.STL" />
      </geometry>
    </collision>
  </link>

  <joint name="lbjoint2" type="continuous">
    <origin xyz="0.053 0 -0.0273" rpy="-1.5708 1.5708 0" />
    <parent link="lb1" />
    <child link="lb2" />
    <axis xyz="-1 0 0" />
  </joint>

  <link name="lb3">
    <inertial>
      <origin xyz="0.013500041538 -0.000357486919 0.105642978108" rpy="0 0 0" />
      <mass value="0.101126826" />
      <inertia ixx="0.000624594596470" ixy="0.000000000006712" ixz="-0.000000000238118"
        iyy="0.000622367653807" iyz="-0.000004386948249" izz="0.000009078971542" />
    </inertial>
    <visual>
      <origin xyz="0 0 0" rpy="0 0 0" />
      <geometry>
        <mesh filename="meshes/lb3.STL" />
      </geometry>
    </visual>
    <collision>
      <origin xyz="0 0 0" rpy="0 0 0" />
      <geometry>
        <mesh filename="meshes/lb3.STL" />
      </geometry>
    </collision>
  </link>

  <joint name="lbjoint3" type="continuous">
    <origin xyz="0.05485 0 0.21" rpy="0 0 0" />
    <parent link="lb2" />
    <child link="lb3" />
    <axis xyz="-1 0 0" />
  </joint>

  <link name="lb4">
    <contact>
      <friction_anchor/>
      <stiffness value="30000.0"/>
      <damping value="1000.0"/>
      <spinning_friction value="0.3"/>
      <lateral_friction value="1.2"/>
    </contact>
    <visual>
      <origin rpy="0 0 0" xyz="0 0 0"/>
      <geometry>
        <sphere radius="0.016"/>
      </geometry>
      <material name="darkgray"/>
    </visual>
    <collision>
      <origin rpy="0 0 0" xyz="0 0 0"/>
      <geometry>
        <sphere radius="0.016"/>
      </geometry>
    </collision>
    <inertial>
      <mass value="0"/>
      <inertia ixx="0" ixy="0" ixz="0" iyy="0" iyz="0" izz="0"/>
    </inertial>
  </link>

  <joint name="lbjoint4" type="fixed">
    <parent link="lb3"/>
    <child link="lb4"/>
    <origin xyz="0.0135 0 0.205"/>
    <dynamics damping="0.0" friction="0.0"/>
  </joint>


    <link name="imu">
      <visual>
        <origin rpy="0 0 0" xyz="0 0 0"/>
        <geometry>
          <sphere radius="0.01"/>
        </geometry>
        <material name="darkgray"/>
      </visual>

      <inertial>
        <mass value="0"/>
        <inertia ixx="0" ixy="0" ixz="0" iyy="0" iyz="0" izz="0"/>
      </inertial>
    </link>

    <joint name="imujoint" type="fixed">
      <parent link="body"/>
      <child link="imu"/>
      <origin xyz="0.0196 0 0.05945"/>
    </joint>

    <link name="point_lfu">
      <visual>
        <origin rpy="0 0 0" xyz="0 0 0"/>
        <geometry>
          <sphere radius="0.01"/>
        </geometry>
        <material name="darkgray"/>
      </visual>

      <inertial>
        <mass value="0.35736635975"/>
        <inertia ixx="0.000016148276679" ixy="0" ixz="0" iyy="0.000016148276679" iyz="0" izz="0.000016148276679"/>
      </inertial>
    </link>

    <joint name="point_lfu_joint" type="fixed">
      <parent link="body"/>
      <child link="point_lfu"/>
      <origin xyz="0.0775 0.071875 0.043625"/>
    </joint>

    <link name="point_rfu">
      <visual>
        <origin rpy="0 0 0" xyz="0 0 0"/>
        <geometry>
          <sphere radius="0.01"/>
        </geometry>
        <material name="darkgray"/>
      </visual>

      <inertial>
        <mass value="0.35736635975"/>
        <inertia ixx="0.000016148276679" ixy="0" ixz="0" iyy="0.000016148276679" iyz="0" izz="0.000016148276679"/>
      </inertial>
    </link>

    <joint name="point_rfu_joint" type="fixed">
      <parent link="body"/>
      <child link="point_rfu"/>
      <origin xyz="0.0775 -0.071875 0.043625"/>
    </joint>

    <link name="point_lbu">
      <visual>
        <origin rpy="0 0 0" xyz="0 0 0"/>
        <geometry>
          <sphere radius="0.01"/>
        </geometry>
        <material name="darkgray"/>
      </visual>

      <inertial>
        <mass value="0.35736635975"/>
        <inertia ixx="0.000016148276679" ixy="0" ixz="0" iyy="0.000016148276679" iyz="0" izz="0.000016148276679"/>
      </inertial>
    </link>

    <joint name="point_lbu_joint" type="fixed">
      <parent link="body"/>
      <child link="point_lbu"/>
      <origin xyz="-0.0775 0.071875 0.043625"/>
    </joint>

    <link name="point_rbu">
      <visual>
        <origin rpy="0 0 0" xyz="0 0 0"/>
        <geometry>
          <sphere radius="0.01"/>
        </geometry>
        <material name="darkgray"/>
      </visual>

      <inertial>
        <mass value="0.35736635975"/>
        <inertia ixx="0.000016148276679" ixy="0" ixz="0" iyy="0.000016148276679" iyz="0" izz="0.000016148276679"/>
      </inertial>
    </link>

    <joint name="point_rbu_joint" type="fixed">
      <parent link="body"/>
      <child link="point_rbu"/>
      <origin xyz="-0.0775 -0.071875 0.043625"/>
    </joint>

    <link name="point_lfd">
      <visual>
        <origin rpy="0 0 0" xyz="0 0 0"/>
        <geometry>
          <sphere radius="0.01"/>
        </geometry>
        <material name="darkgray"/>
      </visual>

      <inertial>
        <mass value="0.35736635975"/>
        <inertia ixx="0.000016148276679" ixy="0" ixz="0" iyy="0.000016148276679" iyz="0" izz="0.000016148276679"/>
      </inertial>
    </link>

    <joint name="point_lfd_joint" type="fixed">
      <parent link="body"/>
      <child link="point_lfd"/>
      <origin xyz="0.0775 0.0780392 -0.0247892"/>
    </joint>

    <link name="point_rfd">
      <visual>
        <origin rpy="0 0 0" xyz="0 0 0"/>
        <geometry>
          <sphere radius="0.01"/>
        </geometry>
        <material name="darkgray"/>
      </visual>

      <inertial>
        <mass value="0.35736635975"/>
        <inertia ixx="0.000016148276679" ixy="0" ixz="0" iyy="0.000016148276679" iyz="0" izz="0.000016148276679"/>
      </inertial>
    </link>

    <joint name="point_rfd_joint" type="fixed">
      <parent link="body"/>
      <child link="point_rfd"/>
      <origin xyz="0.0775 -0.0780392 -0.0247892"/>
    </joint>

    <link name="point_lbd">
      <visual>
        <origin rpy="0 0 0" xyz="0 0 0"/>
        <geometry>
          <sphere radius="0.01"/>
        </geometry>
        <material name="darkgray"/>
      </visual>

      <inertial>
        <mass value="0.35736635975"/>
        <inertia ixx="0.000016148276679" ixy="0" ixz="0" iyy="0.000016148276679" iyz="0" izz="0.000016148276679"/>
      </inertial>
    </link>

    <joint name="point_lbd_joint" type="fixed">
      <parent link="body"/>
      <child link="point_lbd"/>
      <origin xyz="-0.0775 0.0780392 -0.0247892"/>
    </joint>

    <link name="point_rbd">
      <visual>
        <origin rpy="0 0 0" xyz="0 0 0"/>
        <geometry>
          <sphere radius="0.01"/>
        </geometry>
        <material name="darkgray"/>
      </visual>

      <inertial>
        <mass value="0.35736635975"/>
        <inertia ixx="0.000016148276679" ixy="0" ixz="0" iyy="0.000016148276679" iyz="0" izz="0.000016148276679"/>
      </inertial>
    </link>

    <joint name="point_rbd_joint" type="fixed">
      <parent link="body"/>
      <child link="point_rbd"/>
      <origin xyz="-0.0775 -0.0780392 -0.0247892"/>
    </joint>

</robot>
